<?xml version="1.0" ?>
<robot name="_Main_Assembly_URDF" xmlns:xacro="http://www.ros.org/wiki/xacro">

<xacro:include filename="$(find _Main_Assembly_URDF_description)/urdf/materials.xacro" />
<xacro:include filename="$(find _Main_Assembly_URDF_description)/urdf/_Main_Assembly_URDF.trans" />
<xacro:include filename="$(find _Main_Assembly_URDF_description)/urdf/_Main_Assembly_URDF.gazebo" />
<link name="base_link">
  <inertial>
    <origin xyz="0.003328936839643353 -0.0035326254525801233 0.017280293529805195" rpy="0 0 0"/>
    <mass value="2.6135266490024827"/>
    <inertia ixx="0.005454" iyy="0.005485" izz="0.009241" ixy="-0.000271" iyz="2e-05" ixz="-1.9e-05"/>
  </inertial>
  <visual>
    <origin xyz="0 0 0" rpy="0 0 0"/>
    <geometry>
      <mesh filename="package://_Main_Assembly_URDF_description/meshes/base_link.stl" scale="0.001 0.001 0.001"/>
    </geometry>
    <material name="silver"/>
  </visual>
  <collision>
    <origin xyz="0 0 0" rpy="0 0 0"/>
    <geometry>
      <mesh filename="package://_Main_Assembly_URDF_description/meshes/base_link.stl" scale="0.001 0.001 0.001"/>
    </geometry>
  </collision>
</link>

<link name="Link_0_1">
  <inertial>
    <origin xyz="-0.0012497524084683297 0.0005637561129757995 0.034399710975383135" rpy="0 0 0"/>
    <mass value="3.7962768236554094"/>
    <inertia ixx="0.006509" iyy="0.006185" izz="0.005948" ixy="3.2e-05" iyz="-5.3e-05" ixz="0.000238"/>
  </inertial>
  <visual>
    <origin xyz="-0.0 -0.0 -0.069" rpy="0 0 0"/>
    <geometry>
      <mesh filename="package://_Main_Assembly_URDF_description/meshes/Link_0_1.stl" scale="0.001 0.001 0.001"/>
    </geometry>
    <material name="silver"/>
  </visual>
  <collision>
    <origin xyz="-0.0 -0.0 -0.069" rpy="0 0 0"/>
    <geometry>
      <mesh filename="package://_Main_Assembly_URDF_description/meshes/Link_0_1.stl" scale="0.001 0.001 0.001"/>
    </geometry>
  </collision>
</link>

<link name="Link_1_1">
  <inertial>
    <origin xyz="-0.03744802829896941 0.057980544776267885 0.12432920375898959" rpy="0 0 0"/>
    <mass value="4.0834910326590155"/>
    <inertia ixx="0.040926" iyy="0.034787" izz="0.010625" ixy="0.001929" iyz="-0.01439" ixz="0.004141"/>
  </inertial>
  <visual>
    <origin xyz="-0.055 0.0 -0.15215" rpy="0 0 0"/>
    <geometry>
      <mesh filename="package://_Main_Assembly_URDF_description/meshes/Link_1_1.stl" scale="0.001 0.001 0.001"/>
    </geometry>
    <material name="silver"/>
  </visual>
  <collision>
    <origin xyz="-0.055 0.0 -0.15215" rpy="0 0 0"/>
    <geometry>
      <mesh filename="package://_Main_Assembly_URDF_description/meshes/Link_1_1.stl" scale="0.001 0.001 0.001"/>
    </geometry>
  </collision>
</link>

<link name="Link_2_1">
  <inertial>
    <origin xyz="0.026575413033108307 0.07184260934640484 -0.025962646301484316" rpy="0 0 0"/>
    <mass value="0.35228153276512575"/>
    <inertia ixx="0.001801" iyy="0.000403" izz="0.001645" ixy="0.000156" iyz="0.000509" ixz="-5.6e-05"/>
  </inertial>
  <visual>
    <origin xyz="-0.0021 -0.105473 -0.378809" rpy="0 0 0"/>
    <geometry>
      <mesh filename="package://_Main_Assembly_URDF_description/meshes/Link_2_1.stl" scale="0.001 0.001 0.001"/>
    </geometry>
    <material name="silver"/>
  </visual>
  <collision>
    <origin xyz="-0.0021 -0.105473 -0.378809" rpy="0 0 0"/>
    <geometry>
      <mesh filename="package://_Main_Assembly_URDF_description/meshes/Link_2_1.stl" scale="0.001 0.001 0.001"/>
    </geometry>
  </collision>
</link>

<link name="Link_3_1">
  <inertial>
    <origin xyz="-0.0004311079663911026 0.04284662749046697 -0.014723887586099327" rpy="0 0 0"/>
    <mass value="1.2383473430987533"/>
    <inertia ixx="0.000895" iyy="0.000847" izz="0.001234" ixy="0.0" iyz="0.000179" ixz="0.0"/>
  </inertial>
  <visual>
    <origin xyz="-0.02255 -0.268921 -0.319143" rpy="0 0 0"/>
    <geometry>
      <mesh filename="package://_Main_Assembly_URDF_description/meshes/Link_3_1.stl" scale="0.001 0.001 0.001"/>
    </geometry>
    <material name="silver"/>
  </visual>
  <collision>
    <origin xyz="-0.02255 -0.268921 -0.319143" rpy="0 0 0"/>
    <geometry>
      <mesh filename="package://_Main_Assembly_URDF_description/meshes/Link_3_1.stl" scale="0.001 0.001 0.001"/>
    </geometry>
  </collision>
</link>

<link name="Link_4_1">
  <inertial>
    <origin xyz="0.05529361364908404 0.012483467285149874 -0.025021978080367435" rpy="0 0 0"/>
    <mass value="1.322679950265537"/>
    <inertia ixx="0.001179" iyy="0.00167" izz="0.001626" ixy="-0.000192" iyz="-1.5e-05" ixz="7.9e-05"/>
  </inertial>
  <visual>
    <origin xyz="-0.022101 -0.323641 -0.321417" rpy="0 0 0"/>
    <geometry>
      <mesh filename="package://_Main_Assembly_URDF_description/meshes/Link_4_1.stl" scale="0.001 0.001 0.001"/>
    </geometry>
    <material name="silver"/>
  </visual>
  <collision>
    <origin xyz="-0.022101 -0.323641 -0.321417" rpy="0 0 0"/>
    <geometry>
      <mesh filename="package://_Main_Assembly_URDF_description/meshes/Link_4_1.stl" scale="0.001 0.001 0.001"/>
    </geometry>
  </collision>
</link>

<link name="Link_EndEffector_1">
  <inertial>
    <origin xyz="0.042482534257022087 0.015241471147103447 -0.0012571698967583367" rpy="0 0 0"/>
    <mass value="0.25848065815444504"/>
    <inertia ixx="0.000113" iyy="0.000228" izz="0.00025" ixy="-4.7e-05" iyz="2e-06" ixz="3e-06"/>
  </inertial>
  <visual>
    <origin xyz="-0.109009 -0.346171 -0.290385" rpy="0 0 0"/>
    <geometry>
      <mesh filename="package://_Main_Assembly_URDF_description/meshes/Link_EndEffector_1.stl" scale="0.001 0.001 0.001"/>
    </geometry>
    <material name="silver"/>
  </visual>
  <collision>
    <origin xyz="-0.109009 -0.346171 -0.290385" rpy="0 0 0"/>
    <geometry>
      <mesh filename="package://_Main_Assembly_URDF_description/meshes/Link_EndEffector_1.stl" scale="0.001 0.001 0.001"/>
    </geometry>
  </collision>
</link>

<joint name="Revolute 9" type="continuous">
  <origin xyz="0.0 0.0 0.069" rpy="0 0 0"/>
  <parent link="base_link"/>
  <child link="Link_0_1"/>
  <axis xyz="0.0 0.0 1.0"/>
</joint>

<joint name="Revolute 10" type="continuous">
  <origin xyz="0.055 -0.0 0.08315" rpy="0 0 0"/>
  <parent link="Link_0_1"/>
  <child link="Link_1_1"/>
  <axis xyz="1.0 0.0 0.0"/>
</joint>

<joint name="Revolute 11" type="continuous">
  <origin xyz="-0.0529 0.105473 0.226659" rpy="0 0 0"/>
  <parent link="Link_1_1"/>
  <child link="Link_2_1"/>
  <axis xyz="1.0 -0.0 0.0"/>
</joint>

<joint name="Revolute 12" type="continuous">
  <origin xyz="0.02045 0.163448 -0.059666" rpy="0 0 0"/>
  <parent link="Link_2_1"/>
  <child link="Link_3_1"/>
  <axis xyz="0.0 0.939693 -0.34202"/>
</joint>

<joint name="Revolute 13" type="continuous">
  <origin xyz="-0.000449 0.05472 0.002274" rpy="0 0 0"/>
  <parent link="Link_3_1"/>
  <child link="Link_4_1"/>
  <axis xyz="0.0 0.34202 0.939693"/>
</joint>

<joint name="Revolute 15" type="continuous">
  <origin xyz="0.086908 0.02253 -0.031032" rpy="0 0 0"/>
  <parent link="Link_4_1"/>
  <child link="Link_EndEffector_1"/>
  <axis xyz="0.939693 0.321394 -0.116978"/>
</joint>

</robot>
