<?xml version="1.0" ?>
<robot name="AssemblyURDF" xmlns:xacro="http://www.ros.org/wiki/xacro">

<xacro:include filename="$(find AssemblyURDF_description)/urdf/materials.xacro" />
<xacro:include filename="$(find AssemblyURDF_description)/urdf/AssemblyURDF.trans" />
<xacro:include filename="$(find AssemblyURDF_description)/urdf/AssemblyURDF.gazebo" />
<link name="base_link">
  <inertial>
    <origin xyz="0.003328936839643353 -0.0035326254525801233 0.017280293529805195" rpy="0 0 0"/>
    <mass value="2.6135266490024827"/>
    <inertia ixx="0.005454" iyy="0.005485" izz="0.009241" ixy="-0.000271" iyz="2e-05" ixz="-1.9e-05"/>
  </inertial>
  <visual>
    <origin xyz="0 0 0" rpy="0 0 0"/>
    <geometry>
      <mesh filename="file://$(find AssemblyURDF_description)/meshes/base_link.stl" scale="0.001 0.001 0.001"/>
    </geometry>
    <material name="silver"/>
  </visual>
  <collision>
    <origin xyz="0 0 0" rpy="0 0 0"/>
    <geometry>
      <mesh filename="file://$(find AssemblyURDF_description)/meshes/base_link.stl" scale="0.001 0.001 0.001"/>
    </geometry>
  </collision>
</link>

<link name="Link_0_1">
  <inertial>
    <origin xyz="-0.0012497524084683297 0.0005637561129757995 0.034399710975383135" rpy="0 0 0"/>
    <mass value="3.7962768236554094"/>
    <inertia ixx="0.006509" iyy="0.006185" izz="0.005948" ixy="3.2e-05" iyz="-5.3e-05" ixz="0.000238"/>
  </inertial>
  <visual>
    <origin xyz="-0.0 -0.0 -0.069" rpy="0 0 0"/>
    <geometry>
      <mesh filename="file://$(find AssemblyURDF_description)/meshes/Link_0_1.stl" scale="0.001 0.001 0.001"/>
    </geometry>
    <material name="silver"/>
  </visual>
  <collision>
    <origin xyz="-0.0 -0.0 -0.069" rpy="0 0 0"/>
    <geometry>
      <mesh filename="file://$(find AssemblyURDF_description)/meshes/Link_0_1.stl" scale="0.001 0.001 0.001"/>
    </geometry>
  </collision>
</link>

<link name="Link_1_1">
  <inertial>
    <origin xyz="-0.037448028298969406 4.427181886681453e-06 0.1371841626150767" rpy="0 0 0"/>
    <mass value="4.0834910326590155"/>
    <inertia ixx="0.040926" iyy="0.041495" izz="0.003917" ixy="-2e-06" iyz="5e-06" ixz="0.004568"/>
  </inertial>
  <visual>
    <origin xyz="-0.055 0.0 -0.15215" rpy="0 0 0"/>
    <geometry>
      <mesh filename="file://$(find AssemblyURDF_description)/meshes/Link_1_1.stl" scale="0.001 0.001 0.001"/>
    </geometry>
    <material name="silver"/>
  </visual>
  <collision>
    <origin xyz="-0.055 0.0 -0.15215" rpy="0 0 0"/>
    <geometry>
      <mesh filename="file://$(find AssemblyURDF_description)/meshes/Link_1_1.stl" scale="0.001 0.001 0.001"/>
    </geometry>
  </collision>
</link>

<link name="Link_2_1">
  <inertial>
    <origin xyz="0.026575413033108303 -0.00017383961737538664 0.07638998375440575" rpy="0 0 0"/>
    <mass value="0.35228153276512575"/>
    <inertia ixx="0.001801" iyy="0.001827" izz="0.000221" ixy="-1e-06" iyz="1e-05" ixz="0.000165"/>
  </inertial>
  <visual>
    <origin xyz="-0.0021 0.0002 -0.402148" rpy="0 0 0"/>
    <geometry>
      <mesh filename="file://$(find AssemblyURDF_description)/meshes/Link_2_1.stl" scale="0.001 0.001 0.001"/>
    </geometry>
    <material name="silver"/>
  </visual>
  <collision>
    <origin xyz="-0.0021 0.0002 -0.402148" rpy="0 0 0"/>
    <geometry>
      <mesh filename="file://$(find AssemblyURDF_description)/meshes/Link_2_1.stl" scale="0.001 0.001 0.001"/>
    </geometry>
  </collision>
</link>

<link name="Link_3_1">
  <inertial>
    <origin xyz="0.0008186932522888518 -0.00043106421897855956 0.04529864505918468" rpy="0 0 0"/>
    <mass value="1.2383473430987533"/>
    <inertia ixx="0.001304" iyy="0.000895" izz="0.000778" ixy="0.0" iyz="0.0" ixz="1.3e-05"/>
  </inertial>
  <visual>
    <origin xyz="-0.02255 3.4e-05 -0.576146" rpy="0 0 0"/>
    <geometry>
      <mesh filename="file://$(find AssemblyURDF_description)/meshes/Link_3_1.stl" scale="0.001 0.001 0.001"/>
    </geometry>
    <material name="silver"/>
  </visual>
  <collision>
    <origin xyz="-0.02255 3.4e-05 -0.576146" rpy="0 0 0"/>
    <geometry>
      <mesh filename="file://$(find AssemblyURDF_description)/meshes/Link_3_1.stl" scale="0.001 0.001 0.001"/>
    </geometry>
  </collision>
</link>

<link name="Link_4_1">
  <inertial>
    <origin xyz="-0.019242955536155716 -0.0001533994800090687 0.058898239358850524" rpy="0 0 0"/>
    <mass value="1.322679950265537"/>
    <inertia ixx="0.001622" iyy="0.00175" izz="0.001104" ixy="0.0" iyz="-0.0" ixz="9e-06"/>
  </inertial>
  <visual>
    <origin xyz="-0.043402 0.000483 -0.626788" rpy="0 0 0"/>
    <geometry>
      <mesh filename="file://$(find AssemblyURDF_description)/meshes/Link_4_1.stl" scale="0.001 0.001 0.001"/>
    </geometry>
    <material name="silver"/>
  </visual>
  <collision>
    <origin xyz="-0.043402 0.000483 -0.626788" rpy="0 0 0"/>
    <geometry>
      <mesh filename="file://$(find AssemblyURDF_description)/meshes/Link_4_1.stl" scale="0.001 0.001 0.001"/>
    </geometry>
  </collision>
</link>

<link name="Link_EndEffector_1">
  <inertial>
    <origin xyz="-0.0029097184513802686 0.002869608724829102 0.04496607660935592" rpy="0 0 0"/>
    <mass value="0.25848065815444504"/>
    <inertia ixx="0.000247" iyy="0.000247" izz="9.7e-05" ixy="-2e-06" iyz="-1e-05" ixz="1e-05"/>
  </inertial>
  <visual>
    <origin xyz="-0.021948 0.000627 -0.719326" rpy="0 0 0"/>
    <geometry>
      <mesh filename="file://$(find AssemblyURDF_description)/meshes/Link_EndEffector_1.stl" scale="0.001 0.001 0.001"/>
    </geometry>
    <material name="silver"/>
  </visual>
  <collision>
    <origin xyz="-0.021948 0.000627 -0.719326" rpy="0 0 0"/>
    <geometry>
      <mesh filename="file://$(find AssemblyURDF_description)/meshes/Link_EndEffector_1.stl" scale="0.001 0.001 0.001"/>
    </geometry>
  </collision>
</link>

<joint name="Revolute 9" type="revolute">
  <origin xyz="0.0 0.0 0.069" rpy="0 0 0"/>
  <parent link="base_link"/>
  <child link="Link_0_1"/>
  <axis xyz="0.0 0.0 1.0"/>
  <limit upper="3.141593" lower="-3.141593" effort="100" velocity="100"/>
</joint>

<joint name="Revolute 10" type="revolute">
  <origin xyz="0.055 -0.0 0.08315" rpy="0 0 0"/>
  <parent link="Link_0_1"/>
  <child link="Link_1_1"/>
  <axis xyz="1.0 0.0 0.0"/>
  <limit upper="1.570796" lower="-1.570796" effort="100" velocity="100"/>
</joint>

<joint name="Revolute 11" type="revolute">
  <origin xyz="-0.0529 -0.0002 0.249998" rpy="0 0 0"/>
  <parent link="Link_1_1"/>
  <child link="Link_2_1"/>
  <axis xyz="1.0 0.0 0.0"/>
  <limit upper="2.181662" lower="-2.181662" effort="100" velocity="100"/>
</joint>

<joint name="Revolute 12" type="revolute">
  <origin xyz="0.02045 0.000166 0.173998" rpy="0 0 0"/>
  <parent link="Link_2_1"/>
  <child link="Link_3_1"/>
  <axis xyz="-0.0 0.0 1.0"/>
  <limit upper="3.141593" lower="-3.141593" effort="100" velocity="100"/>
</joint>

<joint name="Revolute 13" type="revolute">
  <origin xyz="0.020852 -0.000449 0.050642" rpy="0 0 0"/>
  <parent link="Link_3_1"/>
  <child link="Link_4_1"/>
  <axis xyz="1.0 0.0 0.0"/>
  <limit upper="1.570796" lower="-1.570796" effort="100" velocity="100"/>
</joint>

<joint name="Revolute 15" type="continuous">
  <origin xyz="-0.021454 -0.000144 0.092538" rpy="0 0 0"/>
  <parent link="Link_4_1"/>
  <child link="Link_EndEffector_1"/>
  <axis xyz="-0.0 -0.0 1.0"/>
</joint>

</robot>
